{
 "cells": [
  {
   "cell_type": "code",
   "execution_count": 3,
   "metadata": {},
   "outputs": [],
   "source": [
    "def test_func():\n",
    "    print(\"Hello, World!\")\n",
    "    raise Exception(\"This is a test exception\")"
   ]
  },
  {
   "cell_type": "code",
   "execution_count": 4,
   "metadata": {},
   "outputs": [
    {
     "name": "stdout",
     "output_type": "stream",
     "text": [
      "Hello, World!\n",
      "An error occurred 0\n",
      "Traceback (most recent call last):\n",
      "  File \"C:\\Users\\ACKI82\\AppData\\Local\\Temp\\ipykernel_52516\\1727865866.py\", line 5, in <module>\n",
      "    test_func()\n",
      "  File \"C:\\Users\\ACKI82\\AppData\\Local\\Temp\\ipykernel_52516\\3555619719.py\", line 3, in test_func\n",
      "    raise Exception(\"This is a test exception\")\n",
      "Exception: This is a test exception\n",
      "\n",
      "Hello, World!\n",
      "An error occurred 1\n",
      "Traceback (most recent call last):\n",
      "  File \"C:\\Users\\ACKI82\\AppData\\Local\\Temp\\ipykernel_52516\\1727865866.py\", line 5, in <module>\n",
      "    test_func()\n",
      "  File \"C:\\Users\\ACKI82\\AppData\\Local\\Temp\\ipykernel_52516\\3555619719.py\", line 3, in test_func\n",
      "    raise Exception(\"This is a test exception\")\n",
      "Exception: This is a test exception\n",
      "\n",
      "Hello, World!\n",
      "An error occurred 2\n",
      "Traceback (most recent call last):\n",
      "  File \"C:\\Users\\ACKI82\\AppData\\Local\\Temp\\ipykernel_52516\\1727865866.py\", line 5, in <module>\n",
      "    test_func()\n",
      "  File \"C:\\Users\\ACKI82\\AppData\\Local\\Temp\\ipykernel_52516\\3555619719.py\", line 3, in test_func\n",
      "    raise Exception(\"This is a test exception\")\n",
      "Exception: This is a test exception\n",
      "\n",
      "Hello, World!\n",
      "An error occurred 3\n",
      "Traceback (most recent call last):\n",
      "  File \"C:\\Users\\ACKI82\\AppData\\Local\\Temp\\ipykernel_52516\\1727865866.py\", line 5, in <module>\n",
      "    test_func()\n",
      "  File \"C:\\Users\\ACKI82\\AppData\\Local\\Temp\\ipykernel_52516\\3555619719.py\", line 3, in test_func\n",
      "    raise Exception(\"This is a test exception\")\n",
      "Exception: This is a test exception\n",
      "\n",
      "Hello, World!\n",
      "An error occurred 4\n",
      "Traceback (most recent call last):\n",
      "  File \"C:\\Users\\ACKI82\\AppData\\Local\\Temp\\ipykernel_52516\\1727865866.py\", line 5, in <module>\n",
      "    test_func()\n",
      "  File \"C:\\Users\\ACKI82\\AppData\\Local\\Temp\\ipykernel_52516\\3555619719.py\", line 3, in test_func\n",
      "    raise Exception(\"This is a test exception\")\n",
      "Exception: This is a test exception\n",
      "\n",
      "Hello, World!\n",
      "An error occurred 5\n",
      "Traceback (most recent call last):\n",
      "  File \"C:\\Users\\ACKI82\\AppData\\Local\\Temp\\ipykernel_52516\\1727865866.py\", line 5, in <module>\n",
      "    test_func()\n",
      "  File \"C:\\Users\\ACKI82\\AppData\\Local\\Temp\\ipykernel_52516\\3555619719.py\", line 3, in test_func\n",
      "    raise Exception(\"This is a test exception\")\n",
      "Exception: This is a test exception\n",
      "\n",
      "Hello, World!\n",
      "An error occurred 6\n",
      "Traceback (most recent call last):\n",
      "  File \"C:\\Users\\ACKI82\\AppData\\Local\\Temp\\ipykernel_52516\\1727865866.py\", line 5, in <module>\n",
      "    test_func()\n",
      "  File \"C:\\Users\\ACKI82\\AppData\\Local\\Temp\\ipykernel_52516\\3555619719.py\", line 3, in test_func\n",
      "    raise Exception(\"This is a test exception\")\n",
      "Exception: This is a test exception\n",
      "\n",
      "Hello, World!\n",
      "An error occurred 7\n",
      "Traceback (most recent call last):\n",
      "  File \"C:\\Users\\ACKI82\\AppData\\Local\\Temp\\ipykernel_52516\\1727865866.py\", line 5, in <module>\n",
      "    test_func()\n",
      "  File \"C:\\Users\\ACKI82\\AppData\\Local\\Temp\\ipykernel_52516\\3555619719.py\", line 3, in test_func\n",
      "    raise Exception(\"This is a test exception\")\n",
      "Exception: This is a test exception\n",
      "\n",
      "Hello, World!\n",
      "An error occurred 8\n",
      "Traceback (most recent call last):\n",
      "  File \"C:\\Users\\ACKI82\\AppData\\Local\\Temp\\ipykernel_52516\\1727865866.py\", line 5, in <module>\n",
      "    test_func()\n",
      "  File \"C:\\Users\\ACKI82\\AppData\\Local\\Temp\\ipykernel_52516\\3555619719.py\", line 3, in test_func\n",
      "    raise Exception(\"This is a test exception\")\n",
      "Exception: This is a test exception\n",
      "\n",
      "Hello, World!\n",
      "An error occurred 9\n",
      "Traceback (most recent call last):\n",
      "  File \"C:\\Users\\ACKI82\\AppData\\Local\\Temp\\ipykernel_52516\\1727865866.py\", line 5, in <module>\n",
      "    test_func()\n",
      "  File \"C:\\Users\\ACKI82\\AppData\\Local\\Temp\\ipykernel_52516\\3555619719.py\", line 3, in test_func\n",
      "    raise Exception(\"This is a test exception\")\n",
      "Exception: This is a test exception\n",
      "\n",
      "max retry count exceeded. The process was not completed.\n"
     ]
    },
    {
     "ename": "Exception",
     "evalue": "max retry count exceeded. The process was not completed.",
     "output_type": "error",
     "traceback": [
      "\u001b[1;31m---------------------------------------------------------------------------\u001b[0m",
      "\u001b[1;31mException\u001b[0m                                 Traceback (most recent call last)",
      "Cell \u001b[1;32mIn[4], line 15\u001b[0m\n\u001b[0;32m     13\u001b[0m \u001b[38;5;28;01melse\u001b[39;00m:\n\u001b[0;32m     14\u001b[0m     \u001b[38;5;28mprint\u001b[39m(\u001b[38;5;124m\"\u001b[39m\u001b[38;5;124mmax retry count exceeded. The process was not completed.\u001b[39m\u001b[38;5;124m\"\u001b[39m)\n\u001b[1;32m---> 15\u001b[0m     \u001b[38;5;28;01mraise\u001b[39;00m \u001b[38;5;167;01mException\u001b[39;00m (\u001b[38;5;124m\"\u001b[39m\u001b[38;5;124mmax retry count exceeded. The process was not completed.\u001b[39m\u001b[38;5;124m\"\u001b[39m)\n",
      "\u001b[1;31mException\u001b[0m: max retry count exceeded. The process was not completed."
     ]
    }
   ],
   "source": [
    "import time # for sleep\n",
    "import traceback # for error message\n",
    "for _ in range(10): # max retry count\n",
    "    try:\n",
    "        test_func()\n",
    "    except Exception as e:\n",
    "        print(\"An error occurred\", _)\n",
    "        print(traceback.format_exc()) # error message\n",
    "        time.sleep(30) # wait 30 seconds\n",
    "    else:\n",
    "        print(\"Succeeded! The process was completed without any errors. Loop was ended.\")\n",
    "        break\n",
    "else:\n",
    "    print(\"max retry count exceeded. The process was not completed.\")\n",
    "    raise Exception (\"max retry count exceeded. The process was not completed.\")"
   ]
  }
 ],
 "metadata": {
  "kernelspec": {
   "display_name": "py3.11.5",
   "language": "python",
   "name": "python3"
  },
  "language_info": {
   "codemirror_mode": {
    "name": "ipython",
    "version": 3
   },
   "file_extension": ".py",
   "mimetype": "text/x-python",
   "name": "python",
   "nbconvert_exporter": "python",
   "pygments_lexer": "ipython3",
   "version": "0.0.0"
  }
 },
 "nbformat": 4,
 "nbformat_minor": 2
}
